<?xml version="1.0" encoding="UTF-8"?>
<robot name="psm_col_updated_joint">
  <joint name="psm_main_insertion_joint" type="prismatic">
    <origin xyz="-0. 0.3753 0. " rpy="0.0000001 -0.0000001 -1.5707964"/>
    <parent link="psm_pitch_end_link"/>
    <child link="psm_main_insertion_link"/>
    <axis xyz="1. 0. 0."/>
    <limit lower="0.0565" upper="0.24" effort="12.0" velocity="1.0"/>
  </joint>
  <joint name="psm_main_insertion_joint_2" type="fixed">
    <origin xyz="-0. 0. 0." rpy="-0.0000001 1.5707963 0. "/>
    <parent link="psm_main_insertion_link"/>
    <child link="psm_main_insertion_link_2"/>
  </joint>
  <joint name="psm_main_insertion_joint_3" type="fixed">
    <origin xyz="-0. 0. 0." rpy="-0.0000001 1.5707963 0. "/>
    <parent link="psm_main_insertion_link"/>
    <child link="psm_main_insertion_link_3"/>
  </joint>
  <joint name="psm_pitch_end_joint" type="revolute">
    <origin xyz="0. 0. 0." rpy="-1.5707964 -0. 1.5707963"/>
    <parent link="psm_yaw_link"/>
    <child link="psm_pitch_end_link"/>
    <axis xyz="1. 0. 0."/>
    <limit lower="-0.9251" upper="0.9251" effort="12.0" velocity="1.0"/>
  </joint>
  <joint name="psm_remote_center_joint" type="fixed">
    <origin xyz="0. 0. 0." rpy="0. 0. 0."/>
    <parent link="psm_base_link"/>
    <child link="psm_remote_center_link"/>
  </joint>
  <joint name="psm_tool_gripper1_joint" type="revolute">
    <origin xyz="0. -0. -0." rpy="0. -0. -0."/>
    <parent link="psm_tool_yaw_link"/>
    <child link="psm_tool_gripper1_link"/>
    <axis xyz="1. 0. 0."/>
    <limit lower="-0.5235988" upper="0." effort="0.1" velocity="0.2"/>
  </joint>
  <joint name="psm_tool_gripper2_joint" type="revolute">
    <origin xyz="0. -0. -0." rpy="0. -0. -0."/>
    <parent link="psm_tool_yaw_link"/>
    <child link="psm_tool_gripper2_link"/>
    <axis xyz="1. 0. 0."/>
    <limit lower="0." upper="0.5235988" effort="0.1" velocity="0.2"/>
  </joint>
  <joint name="psm_tool_pitch_joint" type="revolute">
    <origin xyz="-0. 0. -0." rpy="-1.5707964 0. 1.5707964"/>
    <parent link="psm_tool_roll_link"/>
    <child link="psm_tool_pitch_link"/>
    <axis xyz="1. 0. 0."/>
    <limit lower="-1.3962999" upper="1.3962999" effort="12.0" velocity="1.0"/>
  </joint>
  <joint name="psm_tool_roll_joint" type="revolute">
    <origin xyz="0.4162 0. -0. " rpy="-0.0000001 0.0000001 0.0000001"/>
    <parent link="psm_main_insertion_link"/>
    <child link="psm_tool_roll_link"/>
    <axis xyz="1. 0. 0."/>
    <limit lower="-4.5378997" upper="4.5378997" effort="12.0" velocity="1.0"/>
  </joint>
  <joint name="psm_tool_tip_joint" type="fixed">
    <origin xyz="0. 0.0093 -0. " rpy="1.5707963 -1.5707963 0. "/>
    <parent link="psm_tool_yaw_link"/>
    <child link="psm_tool_tip_link"/>
  </joint>
  <joint name="psm_tool_yaw_joint" type="revolute">
    <origin xyz="-0. 0. -0.0091" rpy="-1.5707963 -0. 1.5707963"/>
    <parent link="psm_tool_pitch_link"/>
    <child link="psm_tool_yaw_link"/>
    <axis xyz="1. 0. 0."/>
    <limit lower="-0.5235988" upper="0.5235988" effort="12.0" velocity="1.0"/>
  </joint>
  <joint name="psm_yaw_joint" type="revolute">
    <origin xyz="0. 0. 0." rpy="3.1415927 0. -1.5707964"/>
    <parent link="psm_base_link"/>
    <child link="psm_yaw_link"/>
    <axis xyz="1. 0. 0."/>
    <limit lower="-1.5883" upper="1.5883" effort="12.0" velocity="1.0"/>
  </joint>
  <joint name="root_joint" type="fixed">
    <origin xyz="0. 0. 0." rpy="0. 0. 0."/>
    <parent link="psm"/>
    <child link="psm_base_link"/>
  </joint>
  <link name="psm"/>
  <link name="psm_base_link">
    <inertial>
      <origin xyz="0. -0.17016 -0.085607" rpy="0. 0. 0."/>
      <mass value="2.0160999"/>
      <inertia ixx="0.0080644" ixy="0." ixz="0." iyy="0.0080644" iyz="0." izz="0.0080644"/>
    </inertial>
  </link>
  <link name="psm_main_insertion_link">
    <inertial>
      <origin xyz="-0.0001093 -0.0040563 0.0098616" rpy="0. 0. 0."/>
      <mass value="0.22491"/>
      <inertia ixx="0.0003473" ixy="0.0000213" ixz="-0.0000262" iyy="0.0002885" iyz="0.0000464" izz="0.0002481"/>
    </inertial>
  </link>
  <link name="psm_main_insertion_link_2" />
  <link name="psm_main_insertion_link_3" />
  <link name="psm_pitch_end_link">
    <inertial>
      <origin xyz="0.0442293 0.27985 0. " rpy="0. 0. 0."/>
      <mass value="2.0910001"/>
      <inertia ixx="0.0403931" ixy="0.0000149" ixz="0.0000009" iyy="0.001701" iyz="-0.00222" izz="0.0401587"/>
    </inertial>
  </link>
  <link name="psm_remote_center_link" />
  <link name="psm_tool_gripper1_link">
    <inertial>
      <origin xyz="0.000196 0.001435 -0.0008848" rpy="0. 0. 0."/>
      <mass value="0.02"/>
      <inertia ixx="0.0000003" ixy="0." ixz="0." iyy="0." iyz="-0." izz="0.0000003"/>
    </inertial>
  </link>
  <link name="psm_tool_gripper2_link">
    <inertial>
      <origin xyz="-0.000196 0.001435 0.0008848" rpy="0. 0. 0."/>
      <mass value="0.02"/>
      <inertia ixx="0.0000003" ixy="-0." ixz="0." iyy="0." iyz="0." izz="0.0000003"/>
    </inertial>
  </link>
  <link name="psm_tool_pitch_link">
    <inertial>
      <origin xyz="0.0035763 0. 0. " rpy="0. 0. 0."/>
      <mass value="0.0002578"/>
      <inertia ixx="0." ixy="-0." ixz="-0." iyy="0." iyz="-0." izz="0."/>
    </inertial>
  </link>
  <link name="psm_tool_roll_link">
    <inertial>
      <origin xyz="0. 0. -0.0058234" rpy="0. 0. 0."/>
      <mass value="0.0003322"/>
      <inertia ixx="0." ixy="0." ixz="-0." iyy="0." iyz="-0." izz="0."/>
    </inertial>
  </link>
  <link name="psm_tool_tip_link">
    <inertial>
      <origin xyz="0. 0. 0." rpy="0. 0. 0."/>
      <mass value="0.1"/>
      <inertia ixx="0.0004" ixy="0." ixz="0." iyy="0.0004" iyz="0." izz="0.0004"/>
    </inertial>
  </link>
  <link name="psm_tool_yaw_link">
    <inertial>
      <origin xyz="0. 0. 0." rpy="0. 0. 0."/>
      <mass value="0.1"/>
      <inertia ixx="0.0000002" ixy="0." ixz="-0." iyy="0.0000002" iyz="0." izz="0."/>
    </inertial>
  </link>
  <link name="psm_yaw_link">
    <inertial>
      <origin xyz="-0.038769 0. 0.527996" rpy="0. 0. 0."/>
      <mass value="1.4705"/>
      <inertia ixx="0.005882" ixy="0." ixz="0." iyy="0.005882" iyz="0." izz="0.005882"/>
    </inertial>
  </link>
</robot>
